Workbook
Name EMITEN: 'DAFTAR EMITEN 2023'!$B$1:$D$964
Name MULTIPLE: 'PASAR KESEBANDINGAN'!$C$40:$C$44
Name MULTIPLES: 'PASAR KESEBANDINGAN'!$C$40:$N$44

Sheet HOME
A1: KERTAS KERJA PENILAIAN BISNIS
A4: Nama Perusahaan | B4: PT. Makmur Jaya Sejati Raya | C4: NPWP: | D4: 314560368-113.000
A5: Jenis Perusahaan | B5: tertutup
A6: Jumlah Saham Beredar | B6: 5280000000
A7: Jumlah Saham yang Dinilai | B7: 1610000000
A8: Proporsi Saham yang Dinilai | B8: =IF(B7/B6>100%,"Data Tidak Valid",IF(B7/B6<=0,"Data Tidak Valid",B7/B6)) -> 0.3
A9: Tahun Transaksi Pengalihan Saham | B9: 2022
A10: Cut off Date | B10: =DATE(B9-1, 12, 31) -> 44561
A11: Akhir Periode Proyeksi Pertama | B11: =DATE(B9, 12, 31) -> 44926
A12: Objek Penilaian | B12: saham
A15: DISCOUNT LACK OF MARKETABILITY | B15: =DLOM!F34 -> 0.4
A16: DISCOUNT LACK OF CONTROL/PREMIUM FOR CONTROL | B16: ='DLOC(PFC)'!E24 -> 0.54
A18: LAPORAN KEUANGAN HISTORIS | B18: PERTIMBANGAN | C18: PROYEKSI | D18: PENDEKATAN PENILAIAN | E18: KESIMPULAN

Sheet DAFTAR EMITEN 2023
A1: 1 | B1: AADI | C1: PT Adaro Andalan Indonesia Tbk | D1: 05 Des 2024
A2: 2 | B2: AALI | C2: Astra Agro Lestari Tbk | D2: 09 Des 1997
A3: 3 | B3: ABBA | C3: Mahaka Media Tbk | D3: 37349
A4: 4 | B4: ABDA | C4: Asuransi Bina Dana Arta Tbk | D4: 32695
A5: 5 | B5: ABMM | C5: ABM Investama Tbk | D5: 06 Des 2011
A6: 6 | B6: ACES | C6: PT Aspirasi Hidup Indonesia Tbk | D6: 39392
A7: 7 | B7: ACRO | C7: PT Samcro Hyosung Adilestari Tbk. | D7: 45302
A8: 8 | B8: ACST | C8: PT Acset Indonusa Tbk. | D8: 41449
A9: 9 | B9: ADCP | C9: PT Adhi Commuter Properti Tbk | D9: 21 Mei 2021
A10: 10 | B10: ADES | C10: Akasha Wira International Tbk Tbk | D10: 34498
A11: 11 | B11: ADHI | C11: PT Adhi Karya (Persero) Tbk. | D11: 38064
A12: 12 | B12: ADMF | C12: Adira Dinamika Multi Finance Tbk | D12: 38077
A13: 13 | B13: ADMG | C13: Polychem Indonesia Tbk | D13: 20 Okt 1993
A14: 14 | B14: ADMR | C14: PT Alamtri Minerals Indonesia Tbk | D14: 44564
A15: 15 | B15: ADRO | C15: Alamtri Resources Indonesia Tbk | D15: 39645
A16: 16 | B16: AEGS | C16: PT Anugerah Spareparts Sejahtera Tbk. | D16: 45180
A17: 17 | B17: AGAR | C17: PT Asia Sejahtera Mina Tbk | D17: 02 Des 2019
A18: 18 | B18: AGII | C18: PT Samator Indo Gas Tbk | D18: 42641
A19: 19 | B19: AGRO | C19: PT Bank Raya Indonesia Tbk | D19: 08 Agt 2003
A20: 20 | B20: AGRS | C20: PT Bank IBK Indonesia Tbk. | D20: 22 Des 2014
A21: 21 | B21: AHAP | C21: Asuransi Harta Aman Pratama Tbk | D21: 33130
A22: 22 | B22: AIMS | C22: PT Artha Mahiya Investama Tbk | D22: 37092
A23: 23 | B23: AISA | C23: PT FKS Food Sejahtera Tbk | D23: 35592
A24: 24 | B24: AKKU | C24: PT Anugerah Kagum Karya Utama Tbk | D24: 38292
A25: 25 | B25: AKPI | C25: Argha Karya Prima Ind. Tbk | D25: 18 Des 1992
A26: 26 | B26: AKRA | C26: PT AKR Corporindo Tbk. | D26: 03 Okt 1994
A27: 27 | B27: AKSI | C27: PT Mineral Sumberdaya Mandiri Tbk | D27: 37085
A28: 28 | B28: ALDO | C28: Alkindo Naratama Tbk | D28: 40736
A29: 29 | B29: ALII | C29: PT Ancara Logistics Indonesia Tbk | D29: 45329
A30: 30 | B30: ALKA | C30: Alakasa Industrindo Tbk | D30: 33066
A31: 31 | B31: ALMI | C31: Alumindo Light Metal Industry Tbk | D31: 35432
A32: 32 | B32: ALTO | C32: Tri Banyan Tirta Tbk | D32: 41100
A33: 33 | B33: AMAG | C33: Asuransi Multi Artha Guna Tbk | D33: 23 Des 2005
A34: 34 | B34: AMAN | C34: PT Makmur Berkah Amanda Tbk. | D34: 43903
A35: 35 | B35: AMAR | C35: PT Bank Amar Indonesia Tbk. | D35: 43839
A36: 36 | B36: AMFG | C36: Asahimas Flat Glass Tbk | D36: 35011
A37: 37 | B37: AMIN | C37: PT Ateliers Mecaniques D Indonesie Tbk. | D37: 10 Des 2015
A38: 38 | B38: AMMN | C38: PT Amman Mineral Internasional Tbk. | D38: 45114
A39: 39 | B39: AMMS | C39: PT Agung Menjangan Mas Tbk | D39: 04 Agt 2022
A40: 40 | B40: AMOR | C40: PT Ashmore Asset Management Indonesia Tbk. | D40: 43844
...

Sheet BALANCE SHEET
A1: =HOME!B4 -> PT RAJA VOLTAMA ELEKTRIK | O1: LEGENDA
A2: Balance Sheet | H2: COMMON SIZE | P2: Komponen Cash Flow Statement, Changes on Working Capital, Current Assets
A3: (IDR) | P3: Komponen Cash Flow Statement, Changes on Working Capital, Current Liabilities
C4: =D4-1 -> 2018 | D4: =E4-1 -> 2019 | E4: =F4-1 -> 2020 | F4: =YEAR(HOME!B10) -> 2021 | H4: 2021 | I4: 2022 | J4: 2023 | K4: AVG | M4: Growth | N4: 2021 | O4: 2022 | P4: 2023 | Q4: AVG
A5: ASSETS
A7: Current Assets
B8: Cash on Hands | F8: 82771246 | H8: =D8/D$27 -> 0.29929419 | I8: =E8/E$27 -> 0.11125799 | J8: =F8/F$27 -> 0.19726242 | K8: =AVERAGE(H8:J8) -> 0.20260487 | N8: =IFERROR((D8-C8)/C8,0) -> -0.45839128 | O8: =IFERROR((E8-D8)/D8,0) -> -0.56690591 | P8: =IFERROR((F8-E8)/E8,0) -> 0.98972752 | Q8: =AVERAGE(N8:P8) -> -0.011856555
B9: Cash on Bank (Deposit) | H9: =D9/D$27 -> 0.012927934 | I9: =E9/E$27 -> 0.1742884 | J9: =F9/F$27 -> 0.28696675 | K9: =AVERAGE(H9:J9) -> 0.15806103 | N9: =IFERROR((D9-C9)/C9,0) -> -0.83000923 | O9: =IFERROR((E9-D9)/D9,0) -> 14.706836 | P9: =IFERROR((F9-E9)/E9,0) -> 0.84775144 | Q9: =AVERAGE(N9:P9) -> 4.9081927
B10: Account Receivable | H10: =D10/D$27 -> 0.18457883 | I10: =E10/E$27 -> 0.09469534 | J10: =F10/F$27 -> 0.10054967 | K10: =AVERAGE(H10:J10) -> 0.12660795 | N10: =IFERROR((D10-C10)/C10,0) -> 1.7609136 | O10: =IFERROR((E10-D10)/D10,0) -> -0.40228239 | P10: =IFERROR((F10-E10)/E10,0) -> 0.19160554 | Q10: =AVERAGE(N10:P10) -> 0.51674559
B11: Deposito | H11: =D11/D$27 -> 0 | I11: =E11/E$27 -> 0 | J11: =F11/F$27 -> 0.029729946 | K11: =AVERAGE(H11:J11) -> 0.0099099821 | N11: =IFERROR((D11-C11)/C11,0) -> 0 | O11: =IFERROR((E11-D11)/D11,0) -> 0 | P11: =IFERROR((F11-E11)/E11,0) -> 0 | Q11: =AVERAGE(N11:P11) -> 0
B12: Inventory | H12: =D12/D$27 -> 0.11208837 | I12: =E12/E$27 -> 0.10703254 | J12: =F12/F$27 -> 0.042324675 | K12: =AVERAGE(H12:J12) -> 0.087148528 | N12: =IFERROR((D12-C12)/C12,0) -> 1.2590721 | O12: =IFERROR((E12-D12)/D12,0) -> 0.11251183 | P12: =IFERROR((F12-E12)/E12,0) -> -0.55622969 | Q12: =AVERAGE(N12:P12) -> 0.27178475
B13: Pembayaran Dimuka | H13: =D13/D$27 -> 0.15307415 | I13: =E13/E$27 -> 0.17800494 | J13: =F13/F$27 -> 0.087127802 | K13: =AVERAGE(H13:J13) -> 0.1394023 | N13: =IFERROR((D13-C13)/C13,0) -> 0 | O13: =IFERROR((E13-D13)/D13,0) -> 0.35481354 | P13: =IFERROR((F13-E13)/E13,0) -> -0.45070561 | Q13: =AVERAGE(N13:P13) -> -0.031964026
B14: Others - PPn Lebih Bayar Kompensasi / PPh Pasal 25 / PPh Pasal 22/23 | H14: =D14/D$27 -> 0 | I14: =E14/E$27 -> 0.13413723 | J14: =F14/F$27 -> 0.069800245 | K14: =AVERAGE(H14:J14) -> 0.067979158 | N14: =IFERROR((D14-C14)/C14,0) -> 0 | O14: =IFERROR((E14-D14)/D14,0) -> 0 | P14: =IFERROR((F14-E14)/E14,0) -> -0.41603331 | Q14: =AVERAGE(N14:P14) -> -0.13867777
A16: Current Assets | C16: =SUM(C8:C14)+SUM(C100:C139) | D16: =SUM(D8:D14)+SUM(D100:D139) | E16: =SUM(E8:E14)+SUM(E100:E139) | F16: =SUM(F8:F14)+SUM(F100:F139)
A18: Non Current Assets
A19: Fixed Asset
B20: Beginning | E20: 21000894104 | F20: 21000894104 | H20: =D20/D$27 -> 0.25374027 | I20: =E20/E$27 -> 0.21944544 | J20: =F20/F$27 -> 0.20780202 | K20: =AVERAGE(H20:J20) -> 0.22699591 | N20: =IFERROR((D20-C20)/C20,0) -> 23.992264 | O20: =IFERROR((E20-D20)/D20,0) -> 0.0075961512 | P20: =IFERROR((F20-E20)/E20,0) -> 0.062682854 | Q20: =AVERAGE(N20:P20) -> 8.0208478
B21: Accumulated Depreciations | E21: -633096847 | F21: -4120916663 | H21: =D21/D$27 -> -0.015703746 | I21: =E21/E$27 -> -0.018861888 | J21: =F21/F$27 -> -0.021563534 | K21: =AVERAGE(H21:J21) -> -0.018709723 | N21: =IFERROR((D21-C21)/C21,0) -> 0.75557943 | O21: =IFERROR((E21-D21)/D21,0) -> 0.3993657 | P21: =IFERROR((F21-E21)/E21,0) -> 0.28296631 | Q21: =AVERAGE(N21:P21) -> 0.47930381
B22: Fixed Assets, Net | C22: =C20+C21 -> 31069618 | D22: =D20+D21 -> 6123781380 | E22: =E20+E21 -> 6012024389 | F22: =F20+F21 -> 6264339945 | N22: =IFERROR((D22-C22)/C22,0) -> 196.0987 | O22: =IFERROR((E22-D22)/D22,0) -> -0.01824967 | P22: =IFERROR((F22-E22)/E22,0) -> 0.041968485 | Q22: =AVERAGE(N22:P22) -> 65.37414
A23: Non Current Assets | C23: 0 | D23: 0 | E23: 0 | F23: 0 | N23: =IFERROR((D23-C23)/C23,0) -> 0 | O23: =IFERROR((E23-D23)/D23,0) -> 0 | P23: =IFERROR((F23-E23)/E23,0) -> 0 | Q23: =AVERAGE(N23:P23) -> 0
A24: Intangible Assets | N24: =IFERROR((D24-C24)/C24,0) -> 0 | O24: =IFERROR((E24-D24)/D24,0) -> 0 | P24: =IFERROR((F24-E24)/E24,0) -> 0 | Q24: =AVERAGE(N24:P24) -> 0
A25: Total Non Current Asset | C25: =C22+C23+C24 -> 31069618 | D25: =D22+D23+D24 -> 6123781380 | E25: =E22+E23+E24 -> 6012024389 | F25: =F22+F23+F24 -> 6264339945 | N25: =IFERROR((D25-C25)/C25,0) -> 196.0987 | O25: =IFERROR((E25-D25)/D25,0) -> -0.01824967 | P25: =IFERROR((F25-E25)/E25,0) -> 0.041968485 | Q25: =AVERAGE(N25:P25) -> 65.37414
A27: ASSETS | C27: =+C16+C25 -> 19200305499 | D27: =+D16+D25 -> 25726226037 | E27: =+E16+E25 -> 29972668851 | F27: =+F16+F25 -> 33636118733
A29: LIABILITIES & EQUITY
A30: Current Liabilities
B31: Bank Loan-Short Term | H31: =D31/D$51 -> 0 | I31: =E31/E$51 -> 0 | J31: =F31/F$51 -> 0.029729946 | K31: =AVERAGE(H31:J31) -> 0.0099099821 | N31: =IFERROR((D31-C31)/C31,0) -> -1 | O31: =IFERROR((E31-D31)/D31,0) -> 0 | P31: =IFERROR((F31-E31)/E31,0) -> 0 | Q31: =AVERAGE(N31:P31) -> -0.33333333
B32: Account Payables | H32: =D32/D$51 -> 0.11692035 | I32: =E32/E$51 -> 0.086056735 | J32: =F32/F$51 -> 0.032590642 | K32: =AVERAGE(H32:J32) -> 0.078522576 | N32: =IFERROR((D32-C32)/C32,0) -> 0.11256727 | O32: =IFERROR((E32-D32)/D32,0) -> -0.14248034 | P32: =IFERROR((F32-E32)/E32,0) -> -0.57500041 | Q32: =AVERAGE(N32:P32) -> -0.20163783
B33: Tax Payable | H33: =D33/D$51 -> 0.029933959 | I33: =E33/E$51 -> 0.012112653 | J33: =F33/F$51 -> 0.014284967 | K33: =AVERAGE(H33:J33) -> 0.018777193 | N33: =IFERROR((D33-C33)/C33,0) -> 0.84216689 | O33: =IFERROR((E33-D33)/D33,0) -> -0.52856213 | P33: =IFERROR((F33-E33)/E33,0) -> 0.32348921 | Q33: =AVERAGE(N33:P33) -> 0.21236466
B34: Others - Hutang Jangka Panjang / Hutang Jangka Pendek | H34: =D34/D$51 -> 0.12745334 | I34: =E34/E$51 -> 0.1123292 | J34: =F34/F$51 -> 0.05033051 | K34: =AVERAGE(H34:J34) -> 0.096704351 | N34: =IFERROR((D34-C34)/C34,0) -> 0 | O34: =IFERROR((E34-D34)/D34,0) -> 0.026811656 | P34: =IFERROR((F34-E34)/E34,0) -> -0.49717239 | Q34: =AVERAGE(N34:P34) -> -0.15678691
A35: Current Liabilities | C35: =SUM(C31:C34)+SUM(C200:C219) | D35: =SUM(D31:D34)+SUM(D200:D219) | E35: =SUM(E31:E34)+SUM(E200:E219) | F35: =SUM(F31:F34)+SUM(F200:F219)
A37: Non Current Liabilities
B38: Bank Loan-Long Term | H38: =D38/D$51 -> 0 | I38: =E38/E$51 -> 0 | J38: =F38/F$51 -> 0 | K38: =AVERAGE(H38:J38) -> 0 | N38: =IFERROR((D38-C38)/C38,0) -> 0 | O38: =IFERROR((E38-D38)/D38,0) -> 0 | P38: =IFERROR((F38-E38)/E38,0) -> 0 | Q38: =AVERAGE(N38:P38) -> 0
B39: Related Party acc. Payable & Employee Benefits | H39: =D39/D$51 -> 0 | I39: =E39/E$51 -> 0 | J39: =F39/F$51 -> 0 | K39: =AVERAGE(H39:J39) -> 0 | N39: =IFERROR((D39-C39)/C39,0) -> 0 | O39: =IFERROR((E39-D39)/D39,0) -> 0 | P39: =IFERROR((F39-E39)/E39,0) -> 0 | Q39: =AVERAGE(N39:P39) -> 0
A40: Non Current Liabilities | C40: =+C38+C39 -> 0 | D40: =+D38+D39 -> 0 | E40: =+E38+E39 -> 0 | F40: =+F38+F39 -> 0 | H40: =D40/D$51 -> 0 | I40: =E40/E$51 -> 0 | J40: =F40/F$51 -> 0 | K40: =AVERAGE(H40:J40) -> 0
A41: LIABILITIES | C41: =+C35+C40 -> 4936833523 | D41: =+D35+D40 -> 7056900624 | E41: =+E35+E40 -> 6309204572 | F41: =+F35+F40 -> 4269636530
A42: Shareholders' Equity
A43: Paid Up Capital | F43: 5280000000 | H43: =D43/D$51 -> 0.077741679 | I43: =E43/E$51 -> 0.066727458 | J43: =F43/F$51 -> 0.059459892 | K43: =AVERAGE(H43:J43) -> 0.067976343 | N43: =IFERROR((D43-C43)/C43,0) -> 0 | O43: =IFERROR((E43-D43)/D43,0) -> 0 | P43: =IFERROR((F43-E43)/E43,0) -> 0 | Q43: =AVERAGE(N43:P43) -> 0
A44: Addition
A45: Retained Earnings
B46: Surplus | H46: =D46/D$51 -> 0.17125922 | I46: =E46/E$51 -> 0.1666231 | J46: =F46/F$51 -> 0.17260692 | K46: =AVERAGE(H46:J46) -> 0.17016308 | N46: =IFERROR((D46-C46)/C46,0) -> 0.19701554 | O46: =IFERROR((E46-D46)/D46,0) -> 0.1335236 | P46: =IFERROR((F46-E46)/E46,0) -> 0.16252809 | Q46: =AVERAGE(N46:P46) -> 0.16435574
...

Sheet INCOME STATEMENT
A1: ='BALANCE SHEET'!A1 -> PT RAJA VOLTAMA ELEKTRIK
A2: Income Statement
A3: (IDR) | H3: COMMON SIZE | M3: HORIZONTAL
C5: =D5-1 -> 2018 | D5: =E5-1 -> 2019 | E5: =F5-1 -> 2020 | F5: =YEAR(HOME!B10) -> 2021 | H5: =D5 -> 2019 | I5: =E5 -> 2020 | J5: =F5 -> 2021 | K5: AVG | M5: 2021 | N5: 2022 | O5: 2023 | P5: AVG
A6: Revenue | C6: =SUM(C100:C119) | D6: =SUM(D100:D119) | E6: =SUM(E100:E119) | F6: =SUM(F100:F119) | H6: =(D6-C6)/C6 -> 0.52397245 | I6: =(E6-D6)/D6 -> 0.1387499 | J6: =(F6-E6)/E6 -> 0.028639681 | K6: =AVERAGE(H6:J6) -> 0.23045401 | M6: =(D6-C6)/C6 -> 0.52397245 | N6: =(E6-D6)/D6 -> 0.1387499 | O6: =(F6-E6)/E6 -> 0.028639681 | P6: =AVERAGE(M6:O6) -> 0.23045401
A7: Cost of Good Sold | C7: =SUM(C200:C219) | D7: =SUM(D200:D219) | E7: =SUM(E200:E219) | F7: =SUM(F200:F219) | H7: =D7/D$6 -> -0.63787859 | I7: =E7/E$6 -> -0.59438383 | J7: =F7/F$6 -> -0.42609069 | K7: =AVERAGE(H7:J7) -> -0.55278437 | M7: =(D7-C7)/C7 -> 0.75453523 | N7: =(E7-D7)/D7 -> 0.061102444 | O7: =(F7-E7)/E7 -> -0.26260815 | P7: =AVERAGE(M7:O7) -> 0.18434317
A8: Gross Profit | C8: =SUM(C6:C7) -> 15248394355 | D8: =SUM(D6:D7) -> 18870106297 | E8: =SUM(E6:E7) -> 24069316044 | F8: =SUM(F6:F7) -> 35031201811 | H8: =D8/D$6 -> 0.36212141 | I8: =E8/E$6 -> 0.40561617 | J8: =F8/F$6 -> 0.57390931 | K8: =AVERAGE(H8:J8) -> 0.44721563
B9: Gross Profit Margin | C9: =+C8/C6 -> 0.44594478 | D9: =+D8/D6 -> 0.36212141 | E9: =+E8/E6 -> 0.40561617 | F9: =+F8/F6 -> 0.57390931 | J9: =J8-I8 -> 0.16829314
A11: Operating Expenses:
B12: Others | H12: =D12/D$6 -> -0.17496348 | I12: =E12/E$6 -> -0.13694158 | J12: =F12/F$6 -> -0.32980409 | K12: =AVERAGE(H12:J12) -> -0.21390305 | M12: =(D12-C12)/C12 -> 0.033665556 | N12: =(E12-D12)/D12 -> -0.10871565 | O12: =(F12-E12)/E12 -> 1.4773306 | P12: =AVERAGE(M12:O12) -> 0.46742684
B13: General & Administrative Overheads | H13: =D13/D$6 -> -0.071088845 | I13: =E13/E$6 -> -0.16059563 | J13: =F13/F$6 -> -0.12134155 | K13: =AVERAGE(H13:J13) -> -0.11767534 | M13: =(D13-C13)/C13 -> 0.43612243 | N13: =(E13-D13)/D13 -> 1.5725309 | O13: =(F13-E13)/E13 -> -0.22278872 | P13: =AVERAGE(M13:O13) -> 0.59528822
A15: Operating Expenses | C15: =SUM(C300:C319) | D15: =SUM(D300:D319) | E15: =SUM(E300:E319) | F15: =SUM(F300:F319) | H15: =D15/D$6 -> -0.24605233 | I15: =E15/E$6 -> -0.29753721 | J15: =F15/F$6 -> -0.45114564 | K15: =AVERAGE(H15:J15) -> -0.33157839 | M15: =(D15-C15)/C15 -> 0.1247303 | N15: =(E15-D15)/D15 -> 0.37702606 | O15: =(F15-E15)/E15 -> 0.55969167 | P15: =AVERAGE(M15:O15) -> 0.35381601
A16: (Exclude Depreciation)
A18: EBITDA | C18: =C8+C15 -> 3848542021 | D18: =D8+D15 -> 6048346987 | E18: =E8+E15 -> 6413419305 | F18: =F8+F15 -> 7493446732 | H18: =D18/D$6 -> 0.11606908 | I18: =E18/E$6 -> 0.10807896 | J18: =F18/F$6 -> 0.12276367 | K18: =AVERAGE(H18:J18) -> 0.11563724 | M18: =(D18-C18)/C18 -> 0.57159437 | N18: =(E18-D18)/D18 -> 0.060359024 | O18: =(F18-E18)/E18 -> 0.16840119 | P18: =AVERAGE(M18:O18) -> 0.26678486
B19: EBITDA margin | D19: =D18/D6 -> 0.11606908 | E19: =E18/E6 -> 0.10807896 | F19: =F18/F6 -> 0.12276367
A21: Depreciation | F21: -600812472
A22: EBIT | C22: =+C18+C21 -> 3838185482 | D22: =+D18+D21 -> 5874471249 | E22: =+E18+E21 -> 6252076314 | F22: =+F18+F21 -> 7333474245 | H22: =D22/D$6 -> 0.11273237 | I22: =E22/E$6 -> 0.10536 | J22: =F22/F$6 -> 0.12014287 | K22: =AVERAGE(H22:J22) -> 0.11274508 | M22: =(D22-C22)/C22 -> 0.53053345 | N22: =(E22-D22)/D22 -> 0.064278988 | O22: =(F22-E22)/E22 -> 0.17296621 | P22: =AVERAGE(M22:O22) -> 0.25592621
B23: EBIT margin | D23: =+D22/D6 -> 0.11273237 | E23: =+E22/E6 -> 0.10536 | F23: =+F22/F6 -> 0.12014287 | H23: =D23/D$6 -> 2.1633585e-12 | I23: =E23/E$6 -> 1.775527e-12 | J23: =F23/F$6 -> 1.9682771e-12 | K23: =AVERAGE(H23:J23) -> 1.9690542e-12
A25: Other Incomes/(Charges):
B26: Interest Income | H26: =D26/D$6 -> 0 | I26: =E26/E$6 -> 0.0024755437 | J26: =F26/F$6 -> 0.0017234746 | K26: =AVERAGE(H26:J26) -> 0.0013996728
B27: Interest Expense | F27: 9259301 | H27: =D27/D$6 -> 0 | I27: =E27/E$6 -> -0.00049510871 | J27: =F27/F$6 -> -0.00031919354 | K27: =AVERAGE(H27:J27) -> -0.00027143408 | M27: =(D27-C27)/C27 -> #DIV/0! | N27: =(E27-D27)/D27 -> #DIV/0! | O27: =(F27-E27)/E27 -> -0.33684232 | P27: =AVERAGE(M27:O27) -> #DIV/0!
A28: Other Incomes/(Charges) | C28: =+C26+C27 -> 0 | D28: =+D26+D27 -> 0 | E28: =+E26+E27 -> 117519272 | F28: =+F26+F27 -> 85716770 | H28: =D28/D$6 -> 0 | I28: =E28/E$6 -> 0.001980435 | J28: =F28/F$6 -> 0.001404281 | K28: =AVERAGE(H28:J28) -> 0.0011282387 | M28: =(D28-C28)/C28 -> #DIV/0! | N28: =(E28-D28)/D28 -> #DIV/0! | O28: =(F28-E28)/E28 -> -0.27061521 | P28: =AVERAGE(M28:O28) -> #DIV/0!
A30: Non Operating Income | C30: =SUM(C400:C419) | D30: =SUM(D400:D419) | E30: =SUM(E400:E419) | F30: =SUM(F400:F419) | H30: =D30/D$6 -> 0 | I30: =E30/E$6 -> 0 | J30: =F30/F$6 -> 0 | K30: =AVERAGE(H30:J30) -> 0 | M30: =(D30-C30)/C30 -> -1 | N30: =(E30-D30)/D30 -> #DIV/0! | O30: =(F30-E30)/E30 -> #DIV/0! | P30: =AVERAGE(M30:O30) -> #DIV/0!
A32: Profit Before Tax | C32: =+C22+C28+C30 -> 4798400000 | D32: =+D22+D28+D30 -> 5874471249 | E32: =+E22+E28+E30 -> 6369595586 | F32: =+F22+F28+F30 -> 7419191015 | H32: =D32/D$6 -> 0.11273237 | I32: =E32/E$6 -> 0.10734044 | J32: =F32/F$6 -> 0.12154715 | K32: =AVERAGE(H32:J32) -> 0.11387332 | M32: =(D32-C32)/C32 -> 0.22425626 | N32: =(E32-D32)/D32 -> 0.084284068 | O32: =(F32-E32)/E32 -> 0.16478211 | P32: =AVERAGE(M32:O32) -> 0.15777415
A33: Corporate Tax | F33: -673813682 | J33: =(F33-E33)/E33 -> 0.17296623
A35: Net Profit After Tax | C35: =+C32+C33 -> 3680698625 | D35: =+D32+D33 -> 4405853437 | E35: =+E32+E33 -> 4994138866 | F35: =+F32+F33 -> 5805826735 | H35: =D35/D$6 -> 0.084549278 | I35: =E35/E$6 -> 0.084161239 | J35: =F35/F$6 -> 0.095115721 | K35: =AVERAGE(H35:J35) -> 0.087942079 | M35: =(D35-C35)/C35 -> 0.19701554 | N35: =(E35-D35)/D35 -> 0.1335236 | O35: =(F35-E35)/E35 -> 0.16252809 | P35: =AVERAGE(M35:O35) -> 0.16435574
B36: Net Profit Margin | D36: =+D35/D6 -> 0.084549278 | E36: =+E35/E6 -> 0.084161239 | F36: =+F35/F6 -> 0.095115721 | I36: =J35-I35 -> 0.010954482
B1000: Penjualan | F1000: 17298993649
B1001: Pembelian Pupuk | F1001: -1681734103
B1002: Pembelian Obat-Obatan | F1002: -567317727
B1003: Beban Ongkos Angkut Pembelian TBS | F1003: -806095500
B1004: Beban Langsir & Muat TBS | F1004: -470963990
B1005: Beban Gaji Pegawai Bag. Lapangan | F1005: -6699039850
B1006: Beban Keperluan Lapangan | F1006: -367647700
B1007: Beban Iuran & Retribusi
B1008: Beban Bahan Bakar Minyak | F1008: -543625269
B1009: Beban STNK & Pajak Kendaraan | F1009: -10767100
B1010: Beban Spare Parts Kendaraan | F1010: -772299645
B1011: Beban Perjalanan Dinas | F1011: -146537000
B1012: Beban Pem. & Perawatan Sarana & Prasarana | F1012: -507940000
...

Sheet CASH FLOW STATEMENT
A1: =HOME!B4 -> PT RAJA VOLTAMA ELEKTRIK
A2: Cash Flow Statement
A3: ='BALANCE SHEET'!A3 -> (IDR)
C4: ='INCOME STATEMENT'!D5 -> 2019 | D4: ='INCOME STATEMENT'!E5 -> 2020 | E4: ='INCOME STATEMENT'!F5 -> 2021 | I4: LEGENDA
A5: EBITDA | C5: ='INCOME STATEMENT'!D18 -> 6048346987 | D5: ='INCOME STATEMENT'!E18 -> 6413419305 | E5: ='INCOME STATEMENT'!F18 -> 7493446732 | J5: ="Angkanya didapat dari saldo "&C4&" - "&C4-1&", karena "&C4-1&" ada LK-nya sehingga diisi sekalian di Balance Sheet biar otomatis nyambung." -> Angkanya didapat dari saldo 2019 - 2018, karena 2018 ada LK-nya sehingga diisi sekalian di Balance Sheet biar otomatis nyambung.
A6: Corporate Tax | C6: ='INCOME STATEMENT'!D33 -> -1468617812 | D6: ='INCOME STATEMENT'!E33 -> -1375456720 | E6: ='INCOME STATEMENT'!F33 -> -1613364280
A7: Changes in Working Capital
B8: Current Assets | C8: =('BALANCE SHEET'!D10+'BALANCE SHEET'!D11+'BALANCE SHEET'!D12+'BALANCE SHEET'!D14)*-1 -> -7632127401 | D8: =(('BALANCE SHEET'!E10+'BALANCE SHEET'!E11+'BALANCE SHEET'!E12+'BALANCE SHEET'!E14)-('BALANCE SHEET'!D10+'BALANCE SHEET'!D11+'BALANCE SHEET'!D12+'BALANCE SHEET'!D14))*-1 -> -2434646395 | E8: =(('BALANCE SHEET'!F10+'BALANCE SHEET'!F11+'BALANCE SHEET'!F12+'BALANCE SHEET'!F14)-('BALANCE SHEET'!E10+'BALANCE SHEET'!E11+'BALANCE SHEET'!E12+'BALANCE SHEET'!E14))*-1 -> 1913225999
B9: Current Liabilities | C9: =('BALANCE SHEET'!D31+'BALANCE SHEET'!D32+'BALANCE SHEET'!D33+'BALANCE SHEET'!D34)-('BALANCE SHEET'!C31+'BALANCE SHEET'!C32+'BALANCE SHEET'!C33+'BALANCE SHEET'!C34) -> 2120067101 | D9: =('BALANCE SHEET'!E31+'BALANCE SHEET'!E32+'BALANCE SHEET'!E33+'BALANCE SHEET'!E34)-('BALANCE SHEET'!D31+'BALANCE SHEET'!D32+'BALANCE SHEET'!D33+'BALANCE SHEET'!D34) -> -747696052 | E9: =('BALANCE SHEET'!F31+'BALANCE SHEET'!F32+'BALANCE SHEET'!F33+'BALANCE SHEET'!F34)-('BALANCE SHEET'!E31+'BALANCE SHEET'!E32+'BALANCE SHEET'!E33+'BALANCE SHEET'!E34) -> -2039568042
A10: Working Capital | C10: =+C8+C9 -> -5512060300 | D10: =+D8+D9 -> -3182342447 | E10: =+E8+E9 -> -126342043
A11: Cash Flow from Operations | C11: =SUM(C5:C9) -> -932331125 | D11: =SUM(D5:D9) -> 1855620138 | E11: =SUM(E5:E9) -> 5753740409
A13: Cash Flow from Non Operations | C13: ='INCOME STATEMENT'!D30 -> 0 | D13: ='INCOME STATEMENT'!E30 -> 0 | E13: ='INCOME STATEMENT'!F30 -> 0
A17: Cash Flow from Investment (Capital Expenditure) | C17: ='FIXED ASSET'!C23*-1 -> 0 | D17: ='FIXED ASSET'!D23*-1 -> -49586000 | E17: ='FIXED ASSET'!E23*-1 -> -412288044
A19: Cash Flow before Financing | C19: =C11+C13+C17 -> -932331125 | D19: =D11+D13+D17 -> 1806034138 | E19: =E11+E13+E17 -> 5341452365
A21: Financing
B22: Equity Injection | C22: 0 | D22: 0 | E22: 0
B23: New Lloan | C23: ='ACC PAYABLES'!C10+'ACC PAYABLES'!C19 -> 0 | D23: ='ACC PAYABLES'!D10+'ACC PAYABLES'!D19 -> 0 | E23: ='ACC PAYABLES'!E10+'ACC PAYABLES'!E19 -> 0
B24: Interenst Payment | C24: ='INCOME STATEMENT'!D27 -> 0 | D24: ='INCOME STATEMENT'!E27 -> -29379815 | E24: ='INCOME STATEMENT'!F27 -> -19483450
B25: Interest Income | C25: ='INCOME STATEMENT'!D26 -> 0 | D25: ='INCOME STATEMENT'!E26 -> 146899087 | E25: ='INCOME STATEMENT'!F26 -> 105200220
B26: Principal Repayment | C26: ='ACC PAYABLES'!C20 -> 0 | D26: ='ACC PAYABLES'!D20 -> 0 | E26: ='ACC PAYABLES'!E20 -> 0
A28: Cash Flow from Financing | C28: =SUM(C22:C26) -> 0 | D28: =SUM(D22:D26) -> 117519272 | E28: =SUM(E22:E26) -> 85716770
A30: Net Cash Flow | C30: =+C11+C13+C17+C28 -> -932331125 | D30: =+D11+D13+D17+D28 -> 1923553410 | E30: =+E11+E13+E17+E28 -> 5427169135
A32: Cash-Beginning Balance | C32: =+'BALANCE SHEET'!C8+'BALANCE SHEET'!C9 -> 16172870131 | D32: =C33 -> 8032296982 | E32: =D33 -> 8558587497
A33: Cash-Ending Balance | C33: ='BALANCE SHEET'!D8+'BALANCE SHEET'!D9 -> 8032296982 | D33: ='BALANCE SHEET'!E8+'BALANCE SHEET'!E9 -> 8558587497 | E33: ='BALANCE SHEET'!F8+'BALANCE SHEET'!F9 -> 16287589891
A35: Cash Ending in Bank | C35: ='BALANCE SHEET'!D9 -> 332586949 | D35: ='BALANCE SHEET'!E9 -> 5223888582 | E35: ='BALANCE SHEET'!F9 -> 9652447673
A36: Cash Ending in Cash on Hand | C36: ='BALANCE SHEET'!D8 -> 7699710033 | D36: ='BALANCE SHEET'!E8 -> 3334698915 | E36: ='BALANCE SHEET'!F8 -> 6635142218

Sheet FIXED ASSET
A1: ='INCOME STATEMENT'!A1 -> PT RAJA VOLTAMA ELEKTRIK
A2: Fixed Asset Schedules
A3: (IDR)
C5: ='BALANCE SHEET'!D4 -> 2019 | D5: =C5+1 -> 2020 | E5: =D5+1 -> 2021
A6: A. Acquisition Costs
A7: Beginning
B8: Land | H8: Isinya Rumus
B9: Building
B10: Equipment, Laboratory, & Machinery
B11: Vehicle & Heavy Equipment
B12: Office Inventory
B13: Electrical
A14: Total | C14: =SUM(C8:C13)+SUM(C100:C139) | D14: =SUM(D8:D13)+SUM(D100:D139) | E14: =SUM(E8:E13)+SUM(E100:E139)
A16: Additions | G16: =$D$5 -> 2020 | H16: =$E$5 -> 2021 | I16: AVERAGE
B17: Land | G17: =IFERROR((D17-C17)/C17,0) -> 0 | H17: =IFERROR((E17-D17)/D17,0) -> 0 | I17: =AVERAGE(G17:H17) -> 0
B18: Building & CIP | G18: =IFERROR((D18-C18)/C18,0) -> 0 | H18: =IFERROR((E18-D18)/D18,0) -> 0 | I18: =AVERAGE(G18:H18) -> 0
B19: Equipment, Laboratory, & Machinery | G19: =IFERROR((D19-C19)/C19,0) -> 0 | H19: =IFERROR((E19-D19)/D19,0) -> 0 | I19: =AVERAGE(G19:H19) -> 0
B20: Vehicle & Heavy Equipment | G20: =IFERROR((D20-C20)/C20,0) -> 0 | H20: =IFERROR((E20-D20)/D20,0) -> 0 | I20: =AVERAGE(G20:H20) -> 0
B21: Office Inventory | G21: =IFERROR((D21-C21)/C21,0) -> 0 | H21: =IFERROR((E21-D21)/D21,0) -> 5.9069504 | I21: =AVERAGE(G21:H21) -> 2.9534752
B22: Electrical | G22: =IFERROR((D22-C22)/C22,0) -> 0 | H22: =IFERROR((E22-D22)/D22,0) -> 0 | I22: =AVERAGE(G22:H22) -> 0
A23: Total | C23: =SUM(C17:C22)+SUM(C140:C179) | D23: =SUM(D17:D22)+SUM(D140:D179) | E23: =SUM(E17:E22)+SUM(E140:E179)
A25: Ending
B26: Land | C26: =+C8+C17 -> 0 | D26: =+D8+D17 -> 0 | E26: =+E8+E17 -> 0
B27: Building | C27: =+C9+C18 -> 4947437500 | D27: =+D9+D18 -> 4947437500 | E27: =+E9+E18 -> 4947437500
B28: Equipment, Laboratory, & Machinery | C28: =+C10+C19 -> 0 | D28: =+D10+D19 -> 0 | E28: =+E10+E19 -> 0
B29: Vehicle & Heavy Equipment | C29: =+C11+C20 -> 1490000000 | D29: =+D11+D20 -> 1490000000 | E29: =+E11+E20 -> 1559800000
B30: Office Inventory | C30: =+C12+C21 -> 90342000 | D30: =+D12+D21 -> 139928000 | E30: =+E12+E21 -> 482416044
B31: Electrical | C31: =+C13+C22 -> 0 | D31: =+D13+D22 -> 0 | E31: =+E13+E22 -> 0
A32: Total | C32: =+C14+C23+SUM(C180:C219) | D32: =+D14+D23+SUM(D180:D219) | E32: =+E14+E23+SUM(E180:E219)
A34: B. Depreciation
A35: Beginning
B36: Land
B37: Building
B38: Equipment, Laboratory, & Machinery
B39: Vehicle & Heavy Equipment
B40: Office Inventory
B41: Electrical
A42: Total | C42: =SUM(C36:C41)+SUM(C220:C259) | D42: =SUM(D36:D41)+SUM(D220:D259) | E42: =SUM(E36:E41)+SUM(E220:E259)
A44: Additions | G44: =$D$5 -> 2020 | H44: =$E$5 -> 2021 | I44: AVERAGE
B45: Land | G45: =IFERROR((D45-C45)/C45,0) -> 0 | H45: =IFERROR((E45-D45)/D45,0) -> 0 | I45: =AVERAGE(G45:H45) -> 0
...

Sheet FINANCIAL RATIO
A1: =HOME!B4 -> PT RAJA VOLTAMA ELEKTRIK
A2: Financial Ratios
B4: Ratio | C4: Formula | D4: =ROIC!B5 -> 2019 | E4: =ROIC!C5 -> 2020 | F4: =ROIC!D5 -> 2021 | G4: Average
A5: Profitability Indicator Ratio | B5: Profitability Indicator Ratio | C5: Formula | D5: Column3 | E5: Column4 | F5: Column5 | G5: Column6
B6: Gross Profit Margin | C6: GP/Sales | D6: ='INCOME STATEMENT'!D9 -> 0.36212141 | E6: ='INCOME STATEMENT'!E9 -> 0.40561617 | F6: ='INCOME STATEMENT'!F9 -> 0.57390931 | G6: =AVERAGE(D6:F6) -> 0.44721563
B7: EBITDA Margin | C7: EBITDA/Sales | D7: ='INCOME STATEMENT'!D19 -> 0.11606908 | E7: ='INCOME STATEMENT'!E19 -> 0.10807896 | F7: ='INCOME STATEMENT'!F19 -> 0.12276367 | G7: =AVERAGE(D7:F7) -> 0.11563724
B8: EBIT Margin | C8: EBIT/Sales | D8: ='INCOME STATEMENT'!D23 -> 0.11273237 | E8: ='INCOME STATEMENT'!E23 -> 0.10536 | F8: ='INCOME STATEMENT'!F23 -> 0.12014287 | G8: =AVERAGE(D8:F8) -> 0.11274508
B9: Net Profit Margin | C9: Net Profit/Sales | D9: ='INCOME STATEMENT'!D36 -> 0.084549278 | E9: ='INCOME STATEMENT'!E36 -> 0.084161239 | F9: ='INCOME STATEMENT'!F36 -> 0.095115721 | G9: =AVERAGE(D9:F9) -> 0.087942079
B10: Return On Asset | C10: Net Profit/Asset | D10: ='INCOME STATEMENT'!D35/'BALANCE SHEET'!D27 -> 0.17125922 | E10: ='INCOME STATEMENT'!E35/'BALANCE SHEET'!E27 -> 0.1666231 | F10: ='INCOME STATEMENT'!F35/'BALANCE SHEET'!F27 -> 0.17260692 | G10: =AVERAGE(D10:F10) -> 0.17016308
B11: Return On Equity | C11: Net Profit/Equity | D11: ='INCOME STATEMENT'!D35/'BALANCE SHEET'!D49 -> 0.23599425 | E11: ='INCOME STATEMENT'!E35/'BALANCE SHEET'!E49 -> 0.21104851 | F11: ='INCOME STATEMENT'!F35/'BALANCE SHEET'!F49 -> 0.19770249 | G11: =AVERAGE(D11:F11) -> 0.21491508
A13: Liquidity Measurement Ratio | B13: Liquidity Measurement Ratio | C13: Formula | D13: Column3 | E13: Column4 | F13: Column5 | G13: Column6
B14: Current Ratio | C14: CA/CL | D14: ='BALANCE SHEET'!D16/'BALANCE SHEET'!D35 -> 2.7777697 | E14: ='BALANCE SHEET'!E16/'BALANCE SHEET'!E35 -> 3.7977283 | F14: ='BALANCE SHEET'!F16/'BALANCE SHEET'!F35 -> 6.4107983 | G14: =AVERAGE(D14:F14) -> 4.3287654
B15: Quick Ratio | C15: (Cash+A/R)/CL | D15: =('BALANCE SHEET'!D8+'BALANCE SHEET'!D9+'BALANCE SHEET'!D10)/'BALANCE SHEET'!D35 -> 1.8111086 | E15: =('BALANCE SHEET'!E8+'BALANCE SHEET'!E9+'BALANCE SHEET'!E10)/'BALANCE SHEET'!E35 -> 1.8063861 | F15: =('BALANCE SHEET'!F8+'BALANCE SHEET'!F9+'BALANCE SHEET'!F10)/'BALANCE SHEET'!F35 -> 4.6068771 | G15: =AVERAGE(D15:F15) -> 2.7414573
B16: Cash Ratio | C16: Cash/CL | D16: =('BALANCE SHEET'!D8+'BALANCE SHEET'!D9)/'BALANCE SHEET'!D35 -> 1.1382188 | E16: =('BALANCE SHEET'!E8+'BALANCE SHEET'!E9)/'BALANCE SHEET'!E35 -> 1.356524 | F16: =('BALANCE SHEET'!F8+'BALANCE SHEET'!F9)/'BALANCE SHEET'!F35 -> 3.8147486 | G16: =AVERAGE(D16:F16) -> 2.1031638
A18: Leverage Ratio | B18: Leverage Ratio | C18: Formula | D18: Column3 | E18: Column4 | F18: Column5 | G18: Column6
B19: Debt to Assets Ratio | C19: Liabilities/Asset | D19: =('BALANCE SHEET'!D35+'BALANCE SHEET'!D40)/'BALANCE SHEET'!D27 -> 0.27430765 | E19: =('BALANCE SHEET'!E35+'BALANCE SHEET'!E40)/'BALANCE SHEET'!E27 -> 0.21049859 | F19: =('BALANCE SHEET'!F35+'BALANCE SHEET'!F40)/'BALANCE SHEET'!F27 -> 0.12693606 | G19: =AVERAGE(D19:F19) -> 0.2039141
B20: Debt to Equity Ratio | C20: Liabilities/Equity | D20: =('BALANCE SHEET'!D35+'BALANCE SHEET'!D40)/'BALANCE SHEET'!D49 -> 0.37799441 | E20: =('BALANCE SHEET'!E35+'BALANCE SHEET'!E40)/'BALANCE SHEET'!E49 -> 0.26662219 | F20: =('BALANCE SHEET'!F35+'BALANCE SHEET'!F40)/'BALANCE SHEET'!F49 -> 0.14539149 | G20: =AVERAGE(D20:F20) -> 0.26333603
B21: Capitalization Ratio | C21: LTD/(LTD+Equity) | D21: ='BALANCE SHEET'!D38/('BALANCE SHEET'!D38+'BALANCE SHEET'!D49) -> 0 | E21: ='BALANCE SHEET'!E38/('BALANCE SHEET'!E38+'BALANCE SHEET'!E49) -> 0 | F21: ='BALANCE SHEET'!F38/('BALANCE SHEET'!F38+'BALANCE SHEET'!F49) -> 0 | G21: =AVERAGE(D21:F21) -> 0
B22: Interest Coverage | C22: EBIT/Interest Expense | D22: =IFERROR(ABS('INCOME STATEMENT'!D22/'INCOME STATEMENT'!D27),0) -> 0 | E22: =IFERROR(ABS('INCOME STATEMENT'!E22/'INCOME STATEMENT'!E27),0) -> 212.80176 | F22: =IFERROR(ABS('INCOME STATEMENT'!F22/'INCOME STATEMENT'!F27),0) -> 376.39506 | G22: =AVERAGE(D22:F22) -> 196.39894
B23: Equity to Total Asset | D23: ='BALANCE SHEET'!D49/'BALANCE SHEET'!D27 -> 0.72569235 | E23: ='BALANCE SHEET'!E49/'BALANCE SHEET'!E27 -> 0.78950141 | F23: ='BALANCE SHEET'!F49/'BALANCE SHEET'!F27 -> 0.87306394 | G23: =AVERAGE(D23:F23) -> 0.7960859
A25: Cash Flow Indicator | B25: Cash Flow Indicator | C25: Column2 | D25: Column3 | E25: Column4 | F25: Column5 | G25: Column6
B26: Operating Cash Flow/Sales | C26: Operating Cash Flow/Sales | D26: ='CASH FLOW STATEMENT'!C11/'INCOME STATEMENT'!D6 -> -0.017891635 | E26: ='CASH FLOW STATEMENT'!D11/'INCOME STATEMENT'!E6 -> 0.031270915 | F26: ='CASH FLOW STATEMENT'!E11/'INCOME STATEMENT'!F6 -> 0.094262401 | G26: =AVERAGE(D26:F26) -> 0.03588056
B27: FCF/Operating Cash Ratio | C27: FCF/Operating Cash Flow | D27: =FCF!C20/'CASH FLOW STATEMENT'!C11 -> 1.3729914 | E27: =FCF!D20/'CASH FLOW STATEMENT'!D11 -> 0.79938136 | F27: =FCF!E20/'CASH FLOW STATEMENT'!E11 -> 0.87273791 | G27: =AVERAGE(D27:F27) -> 1.0150369
B28: Short Term Debt Coverage | C28: Operating Cash Flow/Bank Loan Short Term | D28: =IFERROR('CASH FLOW STATEMENT'!C11/'BALANCE SHEET'!D31,0) -> 0 | E28: =IFERROR('CASH FLOW STATEMENT'!D11/'BALANCE SHEET'!E31,0) -> 0 | F28: =IFERROR('CASH FLOW STATEMENT'!E11/'BALANCE SHEET'!F31,0) -> 5.7537404 | G28: =AVERAGE(D28:F28) -> 1.9179135
B30: Capex Coverage | C30: Operating CF/Capex | D30: =IFERROR(ABS('CASH FLOW STATEMENT'!C11/'CASH FLOW STATEMENT'!C17),0) -> 0 | E30: =IFERROR(ABS('CASH FLOW STATEMENT'!D11/'CASH FLOW STATEMENT'!D17),0) -> 37.422259 | F30: =IFERROR(ABS('CASH FLOW STATEMENT'!E11/'CASH FLOW STATEMENT'!E17),0) -> 13.955632 | G30: =AVERAGE(D30:F30) -> 17.125964

Sheet FCF
A1: =HOME!B4 -> PT RAJA VOLTAMA ELEKTRIK
A2: Free Cash Flow
A3: ='BALANCE SHEET'!A3 -> (IDR)
C5: =NOPLAT!C5 -> 2019 | D5: =NOPLAT!D5 -> 2020 | E5: =NOPLAT!E5 -> 2021
A7: NOPLAT | C7: =NOPLAT!C19 -> 4405853437 | D7: =NOPLAT!D19 -> 4876619594 | E7: =NOPLAT!E19 -> 5720109965
A8: Add: Depreciation | C8: ='FIXED ASSET'!C51*-1 -> -173875738 | D8: ='FIXED ASSET'!D51*-1 -> -161342991 | E8: ='FIXED ASSET'!E51*-1 -> -159972488
A9: Gross Cash Flow | C9: =+C7+C8 -> 4231977699 | D9: =+D7+D8 -> 4715276603 | E9: =+E7+E8 -> 5560137477
A11: Changes in Working Capital
A12: (Increase) Decrease in Current Asset | C12: ='CASH FLOW STATEMENT'!C8 -> -7632127401 | D12: ='CASH FLOW STATEMENT'!D8 -> -2434646395 | E12: ='CASH FLOW STATEMENT'!E8 -> 1913225999
A13: Increase (Decrease) in Current Liabilities | C13: ='CASH FLOW STATEMENT'!C9 -> 2120067101 | D13: ='CASH FLOW STATEMENT'!D9 -> -747696052 | E13: ='CASH FLOW STATEMENT'!E9 -> -2039568042
A14: Total Net Changes in Working Capital | C14: ='CASH FLOW STATEMENT'!C10 -> -5512060300 | D14: ='CASH FLOW STATEMENT'!D10 -> -3182342447 | E14: ='CASH FLOW STATEMENT'!E10 -> -126342043
A16: Less: Capital Expenditures | C16: ='FIXED ASSET'!C23*-1 -> 0 | D16: ='FIXED ASSET'!D23*-1 -> -49586000 | E16: ='FIXED ASSET'!E23*-1 -> -412288044
A18: Gross Investment | C18: =+C14+C16 -> -5512060300 | D18: =+D14+D16 -> -3231928447 | E18: =+E14+E16 -> -538630087
A20: Free Cash Flow | C20: =+C9+C18 -> -1280082601 | D20: =+D9+D18 -> 1483348156 | E20: =+E9+E18 -> 5021507390

Sheet NOPLAT
A1: =HOME!B4 -> PT RAJA VOLTAMA ELEKTRIK
A2: NOPLAT
A3: ='BALANCE SHEET'!A3 -> (IDR)
C5: ='ACC PAYABLES'!C5 -> 2019 | D5: ='ACC PAYABLES'!D5 -> 2020 | E5: ='ACC PAYABLES'!E5 -> 2021
A7: Profit Before Tax | C7: ='INCOME STATEMENT'!D32 -> 5874471249 | D7: ='INCOME STATEMENT'!E32 -> 6369595586 | E7: ='INCOME STATEMENT'!F32 -> 7419191015
A8: Add: Interest Expenses | C8: ='INCOME STATEMENT'!D27*-1 -> 0 | D8: ='INCOME STATEMENT'!E27*-1 -> 29379815 | E8: ='INCOME STATEMENT'!F27*-1 -> 19483450
A9: Less: Interest Income | C9: ='INCOME STATEMENT'!D26*-1 -> 0 | D9: ='INCOME STATEMENT'!E26*-1 -> -146899087 | E9: ='INCOME STATEMENT'!F26*-1 -> -105200220
A10: Non Operating Income | C10: ='INCOME STATEMENT'!D30*-1 -> 0 | D10: ='INCOME STATEMENT'!E30*-1 -> 0 | E10: ='INCOME STATEMENT'!F30*-1 -> 0
A11: EBIT | C11: =SUM(C7:C10) -> 5874471249 | D11: =SUM(D7:D10) -> 6252076314 | E11: =SUM(E7:E10) -> 7333474245
A13: Tax Provision from Income Statement | C13: ='INCOME STATEMENT'!D33*-1 -> 1468617812 | D13: ='INCOME STATEMENT'!E33*-1 -> 1375456720 | E13: ='INCOME STATEMENT'!F33*-1 -> 1613364280
A14: Add: Tax Shield on Interest Expenses | C14: ='INCOME STATEMENT'!$B$33*'INCOME STATEMENT'!D27*-1 -> 0 | D14: ='INCOME STATEMENT'!$B$33*'INCOME STATEMENT'!E27*-1 -> 0 | E14: ='INCOME STATEMENT'!$B$33*'INCOME STATEMENT'!F27*-1 -> 0
A15: Less: Tax on Interest Income | C15: ='INCOME STATEMENT'!$B$33*'INCOME STATEMENT'!D26*-1 -> 0 | D15: ='INCOME STATEMENT'!$B$33*'INCOME STATEMENT'!E26*-1 -> 0 | E15: ='INCOME STATEMENT'!$B$33*'INCOME STATEMENT'!F26*-1 -> 0
A16: Tax on Non Operating Income | C16: ='INCOME STATEMENT'!$B$33*'INCOME STATEMENT'!D30*-1 -> 0 | D16: ='INCOME STATEMENT'!$B$33*'INCOME STATEMENT'!E30*-1 -> 0 | E16: ='INCOME STATEMENT'!$B$33*'INCOME STATEMENT'!F30*-1 -> 0
A17: Total Taxes on EBIT | C17: =SUM(C13:C16) -> 1468617812 | D17: =SUM(D13:D16) -> 1375456720 | E17: =SUM(E13:E16) -> 1613364280
A19: NOPLAT | C19: =C11-C17 -> 4405853437 | D19: =D11-D17 -> 4876619594 | E19: =E11-E17 -> 5720109965

Sheet ROIC
A1: =HOME!B4 -> PT RAJA VOLTAMA ELEKTRIK
A2: ROIC
A3: ='BALANCE SHEET'!A3 -> (IDR)
B5: ='BALANCE SHEET'!D4 -> 2019 | C5: =B5+1 -> 2020 | D5: =C5+1 -> 2021
A7: NOPLAT | B7: =FCF!C20 -> -1280082601 | C7: =FCF!D20 -> 1483348156 | D7: =FCF!E20 -> 5021507390
A8: Total Asset in Balance Sheet | B8: ='BALANCE SHEET'!D27 -> 25726226037 | C8: ='BALANCE SHEET'!E27 -> 29972668851 | D8: ='BALANCE SHEET'!F27 -> 33636118733
A9: Less Non Operating Fixed Assets *) | F9: Asumsi ini sesuai dengan Laporan Penilaian Wajib Pajak bahwa Kas dan Deposito adalah Non Operating Asset
A10: Less Excess Cash **) | B10: ='BALANCE SHEET'!D8*-1 -> -7699710033 | C10: ='BALANCE SHEET'!E8*-1 -> -3334698915 | D10: ='BALANCE SHEET'!F8*-1 -> -6635142218
A11: Less Marketable Securities | B11: 0 | C11: 0 | D11: 0
A12: Total Invested Capital at End of Year | B12: =SUM(B8:B11) -> 18026516004 | C12: =SUM(C8:C11) -> 26637969936 | D12: =SUM(D8:D11) -> 27000976515
A13: Total Invested Capital at Beginning of Year | C13: =B12 -> 18026516004 | D13: =C12 -> 26637969936
A15: ROIC = NOPLAT/Inves Capital Beginning of Year | C15: =C7/C13 -> 0.082287013 | D15: =D7/D13 -> 0.18850939
A18: Catatan
A19: *)Book Value Asset yang menganggur (idle) tidak digunakan untuk operasional
A20: **)Asumsi Idle Cash tiap tahun

Sheet DLOC(PFC)
A2: PERTIMBANGAN PREMI FOR CONTROL (PFC)
A4: NO | B4: FAKTOR PERTIMBANGAN | C4: KONDISI PERUSAHAAN DENGAN PEMEGANG SAHAM | D4: KONFIRMASI | E4: NILAI KENDALI
A7: 1 | B7: Perjanjian antara Pemegang Saham | C7: Apakah terdapat perjanjian dari pemegang saham yang mengatur posisi dalam susunan manajemen perusahaan yang akan menjalankan perusahaan tanpa melihat jumlah kepemilikan saham? (Ada/Tidak Ada) | E7: Ada | F7: =IF(E7="Ada",0,1) -> 1 | G7: Belum ada dokumen yang mendukung jawaban "Ada" | H7: Ada | I7: Rendah | J7: Rendah | K7: Tidak Ada | L7: Tidak
H8: Tidak Ada | I8: Sedang | J8: Moderat | K8: Sebagian | L8: Sebagian
A9: 2 | B9: Kerugian Saham Minoritas | C9: Besarnya kerugian pemegang saham minoritas dari perusahaan tertutup apabila dibandingkan dengan pemegang saham minoritas perusahaan terbuka? (Rendah, Sedang atau Tinggi) | E9: Rendah | F9: =IF(E9="Rendah",0,IF(E9="Sedang",0.5,1)) -> 0.5 | G9: Perusahaan tidak pernah rugi sejak 2018-2021 | I9: Tinggi | J9: Dominan | K9: Seluruhnya | L9: Ya
A11: 3 | B11: Pemegang Saham Pengendali | C11: Hal-hal yang dilakukan oleh pemegang saham pengendali terhadap perusahaan yang dikendalikan untuk membuat saham yang dimilikinya lebih menguntungkan? (Rendah, Moderat atau Dominan) | E11: Moderat | F11: =IF(E11="Rendah",0,IF(E11="Moderat",0.5,1)) -> 0.5 | G11: Pemegang Saham Mayoritas juga bertindak sebagai Direktur sejak 2018-2021
A13: 4 | B13: Penunjukkan Manajemen | C13: Apakah manajemen perusahaan ditunjuk oleh pemegang saham mayoritas? (Tidak Ada, Sebagian atau Seluruhnya) | E13: Sebagian | F13: =IF(E13="Tidak Ada",0,IF(E13="Sebagian",0.5,1)) -> 0.5 | G13: Pemegang Saham Mayoritas juga bertindak sebagai Direktur sejak 2018-2021 namun Pemegang Saham Minoritas tidak bertindak sebagai Pengurus
A15: 5 | B15: Pengendalian Operasional Perusahaan | C15: Apakah pemegang saham mayoritas sebagai pengendali operasional perusahaan? (Tidak, Sebagian atau Ya) | E15: Tidak | F15: =IF(E15="Tidak",0,IF(E15="Sebagian",0.5,1)) -> 0.5 | G15: Pengurus terdiri dari Pemegang Saham Mayoritas (sebagai Direktur) dan Non-Pemegang Saham (sebagai Komisaris)
A17: JUMLAH | F17: =SUM(F7:F16) -> 3
A20: =IF(B20="DLOC Perusahaan tertutup ",1,2) -> 1 | B20: =IF(HOME!B5="tertutup","DLOC Perusahaan tertutup ","DLOC Perusahaan terbuka ") -> DLOC Perusahaan tertutup | C20: ="Perhitungan "&RIGHT(A2,6) -> Perhitungan (PFC)
A21: =IF(B31="Minoritas",5,7) -> 7 | B21: mayoritas | C21: Maksimum Skor | E21: 5
B22: =IF(A20=1," 30% - 70%"," 20% - 35%") -> 30% - 70% | C22: PREMI FOR CONTROL (PFC) 30% - 70% | E22: =RIGHT(B22,3)-LEFT(B22,4) -> 0.4
C23: Jumlah Skor | E23: =F17 -> 3
C24: DLOC Objek Penilaian | E24: =LEFT(B22,4)+(E23/E21*E22) -> 0.54
D26: Paling Tinggi | E26: 0.7
D27: Moderat | E27: 0.5
D28: Paling Rendah | E28: 0.3

Sheet DLOM
B2: PERTIMBANGAN DISCOUNT LACK OF MARKETABILITY (DLOM)
B4: NO | C4: FAKTOR PERTIMBANGAN | D4: KONDISI PERUSAHAAN DALAM INDUSTRI | E4: KONFIRMASI | F4: NILAI MAKETABILITAS
B7: 1 | C7: Entry Barier Perijinan Usaha | D7: Apakah telah ada pembatasan atas perijinan usaha, namun banyak investor yang berminat disebabkan prospek usaha dibidang industri tersebut memiliki prospek yang cerah? (Ada, Terbatas atau Tidak Ada) | F7: Tidak Ada | G7: =IF(F7="Ada",0,IF(F7="Terbatas",0.5,1)) -> 1 | I7: Ada | J7: Tidak Terbatas | K7: Ya | L7: Diatas | M7: Tidak, Meningkat
I8: Terbatas | J8: Segmen Tertentu | K8: Kadang-kadang | L8: Rata-rata | M8: Sedang, Stabil
B9: 2 | C9: Entry Barier Skala Ekonomis Usaha | D9: Apakah untuk industri tersebut membutuhkan skala ekonomis usaha yang besar, sehingga hanya investor tertentu dengan modal besar yang dapat masuk dibidang industri tersebut? (Tidak Terbatas, Segmen Tertentu atau Skala Besar) | F9: Skala Besar | G9: =IF(F9="Tidak Terbatas",0,IF(F9="Segmen Tertentu",0.5,1)) -> 1 | I9: Tidak Ada | J9: Skala Besar | K9: Tidak Ada | L9: Dibawah | M9: Ya, Menurun
B11: 3 | C11: Dividen | D11: Apakah kebijakan dividen perusahaan telah diputuskan setiap tahun melalui RUPS, serta ada pembagian dividen setiap tahun? (Ya, Kadang-kadang atau Tidak Ada) | F11: Kadang-kadang | G11: =IF(F11="Ya",0,IF(F11="Kadang-kadang",0.5,1)) -> 1 | I11: Dibawah | J11: Diatas | K11: Lebih Besar | L11: Meningkat | M11: Ya
I12: Rata-rata | J12: Rata-rata | K12: Rata-rata | L12: Seperti Saat Ini | M12: Seperti Saat Ini
B13: 4 | C13: Profitabilitas (EBITDA) | D13: Apakah tingkat profitabilitas (EBITDA) perusahaan sesuai dengan tingkat profitabilitas industri sejenis? (Diatas, Rata-Rata atau Dibawah) | F13: Rata-rata | G13: =IF(F13="Diatas",0,IF(F13="Rata-rata",0.5,1)) -> 1 | I13: Diatas | J13: Dibawah | K13: Lebih Kecil | L13: Menurun | M13: Tidak
B15: 5 | C15: Fluktuasi Laba Bersih | D15: Apakah laba bersih perusahaan berfluktuasi? (Tidak, Meningkat; Sedang, Stabil; atau, Ya, Menurun) | F15: Tidak, Meningkat | G15: =IF(F15="Tidak, Meningkat",0,IF(F15="Sedang, Stabil",0.5,1)) -> 1
B17: 6 | C17: Struktur Permodalan | D17: Apakah struktur permodalan (Debt to Equity Ratio) perusahaan sesuai dengan rata-rata industri sejenis? (Dibawah, Rata-Rata atau Diatas) | F17: Rata-rata | G17: =IF(F17="Dibawah",0,IF(F17="Rata-rata",0.5,1)) -> 1
B19: 7 | C19: Liquiditas | D19: Apakah liquiditas (Current Ratio) perusahaan sesuai dengan rata-rata industri sejenis? (Diatas, Rata-Rata atau Dibawah) | F19: Rata-rata | G19: =IF(F19="Diatas",0,IF(F19="Rata-rata",0.5,1)) -> 1
B21: 8 | C21: Pertumbuhan Penjualan | D21: Pertumbuhan penjualan perusahaan dibandingkan dengan rata-rata industri sejenis? (Lebih Besar, Rata-Rata atau Lebih Kecil) | F21: Rata-rata | G21: =IF(F21="Lebih Besar",0,IF(F21="Rata-rata",0.5,1)) -> 1
B23: 9 | C23: Prospek Perusahaan dan Industri | D23: Bagaimana Prospek perusahaan maupun industrinya dimasa mendatang? (Meningkat, Seperti saat ini atau Menurun) | F23: Meningkat | G23: =IF(F23="Meningkat",0,IF(F23="Seperti Saat Ini",0.5,1)) -> 1
B25: 10 | C25: Kualitas Manajemen | D25: Apakah kualitas manajemen perusahaan dapat mencapai tingkat keberhasilan operasi dan keuangan perusahaan serta mempunyai probabilitas yang tinggi untuk memperoleh hasil yang diharapkan? (Ya, Seperti Saat Ini atau Tidak) | F25: Ya | G25: =IF(F25="Ya",0,IF(F25="Seperti Saat Ini",0.5,1)) -> 1
B27: JUMLAH | G27: =SUM(G7:G26) -> 10
B30: =IF(C30="DLOM Perusahaan tertutup ",1,2) -> 1 | C30: DLOM Perusahaan tertutup | D30: Perhitungan DLOM
B31: =IF(C31="Minoritas",5,7) -> 7 | C31: mayoritas | D31: Maksimum Skor | F31: 10
C32: =IF(B30+B31=6,"30% - 50%",IF(B30+B31=8,"20% - 40%",IF(B30+B31=7,"10% - 30%",IF(B30+B31=9,"0% - 20%","-")))) -> 20% - 40% | D32: =C30&C32 -> DLOM Perusahaan tertutup 20% - 40% | F32: =RIGHT(C32,3)-LEFT(C32,3) -> 0.2
D33: Jumlah Skor | F33: =G27 -> 10
D34: DLOM Objek Penilaian | F34: =LEFT(C32,3)+(F33/F31*F32) -> 0.4
F37: DER PERUSAHAAN GARMEN STATISTIK 30 JUNI 2020
C38: Paling Tinggi | D38: 0.2 | F38: -1.94
C39: Moderat | D39: 0.3 | F39: 1.35
C40: Paling Rendah | D40: 0.4 | F40: -11.4
F41: -11.4
E42: ERATEX | F42: 2.68
F43: 3.27
F44: 8.12
F45: 1.02
F46: 11.7
F47: 1.37
F48: 1.05
F49: -1.24
F50: 3.03
F51: 2.02
F52: 1.6
F53: 1.24
F54: 0.18
... F59: 1.19
F60: =AVERAGE(F38:F59) -> 0.73272727

Sheet TL
N2: Cuti Off Date
P9: SUBSEQUENT EVENT
C10: ='BALANCE SHEET'!E4 -> 2020 | H10: ? | L10: ='BALANCE SHEET'!F4 -> 2021 | Q10: =L10+1 -> 2022
C11: Net Profit | D11: ='INCOME STATEMENT'!E35 -> 4994138866 | H11: Net Profit | L11: Net Profit | M11: ='INCOME STATEMENT'!F35 -> 5805826735 | Q11: Net Profit | R11: 135354171907
C12: Ekuitas | D12: ='BALANCE SHEET'!E49 -> 23663464279 | H12: Ekuitas | L12: Ekuitas | M12: ='BALANCE SHEET'!F49 -> 29366482204 | Q12: Ekuitas | R12: 635570945239
C13: DER | D13: ='FINANCIAL RATIO'!E20 -> 0.26662219 | H13: DER | L13: DER | M13: ='FINANCIAL RATIO'!F20 -> 0.14539149 | Q13: DER | R13: =215053803953/R12 -> 0.33836318
C14: NPM | D14: ='FINANCIAL RATIO'!E9 -> 0.084161239 | H14: NPM | L14: NPM | M14: ='FINANCIAL RATIO'!F9 -> 0.095115721 | Q14: NPM | R14: =R11/1395998575702 -> 0.096958675

Sheet DASHBOARD
M2: HISTORIS | U2: PROYEKSI
R50: Cuti Off Date
T57: SUBSEQUENT EVENT
G58: =TL!C10 -> 2020 | L58: =TL!H10 -> ? | P58: =TL!L10 -> 2021 | U58: =P58+1 -> 2022
G59: Net Profit | H59: =TL!D11 -> 4994138866 | L59: =TL!H11 -> Net Profit | M59: =TL!I11 -> 0 | P59: Net Profit | Q59: =TL!M11 -> 5805826735 | U59: Net Profit | V59: =TL!R11 -> 135354171907
G60: Ekuitas | H60: =TL!D12 -> 23663464279 | L60: =TL!H12 -> Ekuitas | M60: =TL!I12 -> 0 | P60: Ekuitas | Q60: =TL!M12 -> 29366482204 | U60: Ekuitas | V60: =TL!R12 -> 635570945239
G61: DER | H61: =TL!D13 -> 0.26662219 | L61: =TL!H13 -> DER | M61: =TL!I13 -> 0 | P61: DER | Q61: =TL!M13 -> 0.14539149 | U61: DER | V61: =TL!R13 -> 0.33836318
G62: NPM | H62: =TL!D14 -> 0.084161239 | L62: =TL!H14 -> NPM | M62: =TL!I14 -> 0 | P62: NPM | Q62: =TL!M14 -> 0.095115721 | U62: NPM | V62: =TL!R14 -> 0.096958675

Sheet INCOME STATEMENT (2)
A1: ='BALANCE SHEET'!A1 -> PT RAJA VOLTAMA ELEKTRIK
A2: Income Statement
A3: (IDR) | H3: COMMON SIZE
C5: ='INCOME STATEMENT'!F5 -> 2021 | D5: =C5+1 -> 2022 | E5: =D5+1 -> 2023 | F5: =E5+1 -> 2024 | H5: =D5 -> 2022 | I5: =E5 -> 2023 | J5: =F5 -> 2024 | K5: AVG
A6: Revenue | C6: ='INCOME STATEMENT'!F6 -> 61039612496 | D6: =C6*(1+'INCOME STATEMENT'!$P$6) -> 7.5106436e+10 | E6: =D6*(1+'INCOME STATEMENT'!$P$6) -> 9.2415015e+10 | F6: =E6*(1+'INCOME STATEMENT'!$P$6) -> 1.1371243e+11 | H6: =(D6-C6)/C6 -> 0.23045401 | I6: =(E6-D6)/D6 -> 0.23045401 | J6: =(F6-E6)/E6 -> 0.23045401 | K6: =AVERAGE(H6:J6) -> 0.23045401
A7: Cost of Good Sold | C7: ='INCOME STATEMENT'!F7 -> -26008410685 | D7: =C7*(1+'INCOME STATEMENT'!$P$7) -> -3.0802884e+10 | E7: =D7*(1+'INCOME STATEMENT'!$P$7) -> -3.6481185e+10 | F7: =E7*(1+'INCOME STATEMENT'!$P$7) -> -4.3206243e+10 | H7: =D7/D$6 -> -0.41012309 | I7: =E7/E$6 -> -0.39475387 | J7: =F7/F$6 -> -0.37996061 | K7: =AVERAGE(H7:J7) -> -0.39494586
A8: Gross Profit | C8: ='INCOME STATEMENT'!F8 -> 35031201811 | D8: =SUM(D6:D7) -> 4.4303552e+10 | E8: =SUM(E6:E7) -> 5.593383e+10 | F8: =SUM(F6:F7) -> 7.0506184e+10 | H8: =D8/D$6 -> 0.58987691 | I8: =E8/E$6 -> 0.60524613 | J8: =F8/F$6 -> 0.62003939 | K8: =AVERAGE(H8:J8) -> 0.60505414
B9: Gross Profit Margin | C9: ='INCOME STATEMENT'!F9 -> 0.57390931 | D9: =+D8/D6 -> 0.58987691 | E9: =+E8/E6 -> 0.60524613 | F9: =+F8/F6 -> 0.62003939 | J9: =J8-I8 -> 0.014793264
A11: Operating Expenses:
B12: Others | C12: ='INCOME STATEMENT'!F12 -> -20131113884 | D12: =C12*(1+'INCOME STATEMENT'!P12) -> -2.9540937e+10 | E12: =D12*(1+'INCOME STATEMENT'!Q12) -> -2.9540937e+10 | F12: =E12*(1+'INCOME STATEMENT'!R12) -> -2.9540937e+10 | H12: =D12/D$6 -> -0.39332098 | I12: =E12/E$6 -> -0.31965516 | J12: =F12/F$6 -> -0.25978636 | K12: =AVERAGE(H12:J12) -> -0.32425417
B13: General & Administrative Overheads | C13: ='INCOME STATEMENT'!F13 -> -7406641195 | D13: =C13*(1+'INCOME STATEMENT'!P13) -> -1.1815727e+10 | E13: =D13*(1+'INCOME STATEMENT'!Q13) -> -1.1815727e+10 | F13: =E13*(1+'INCOME STATEMENT'!R13) -> -1.1815727e+10 | H13: =D13/D$6 -> -0.15731977 | I13: =E13/E$6 -> -0.12785506 | J13: =F13/F$6 -> -0.10390885 | K13: =AVERAGE(H13:J13) -> -0.12969456
A15: Operating Expenses | C15: ='INCOME STATEMENT'!F15 -> -27537755079 | D15: =D12+D13 -> -4.1356664e+10 | E15: =E12+E13 -> -4.1356664e+10 | F15: =F12+F13 -> -4.1356664e+10 | H15: =D15/D$6 -> -0.55064075 | I15: =E15/E$6 -> -0.44751022 | J15: =F15/F$6 -> -0.36369521 | K15: =AVERAGE(H15:J15) -> -0.45394873
A16: (exclude depreciation)
A18: EBITDA | C18: ='INCOME STATEMENT'!F18 -> 7493446732 | D18: =D8+D15 -> 2.9468881e+09 | E18: =E8+E15 -> 1.4577166e+10 | F18: =F8+F15 -> 2.9149519e+10 | H18: =D18/D$6 -> 0.039236159 | I18: =E18/E$6 -> 0.1577359 | J18: =F18/F$6 -> 0.25634419 | K18: =AVERAGE(H18:J18) -> 0.15110542
B19: EBITDA margin | C19: ='INCOME STATEMENT'!F19 -> 0.12276367 | D19: =D18/D6 -> 0.039236159 | E19: =E18/E6 -> 0.1577359 | F19: =F18/F6 -> 0.25634419
A21: Depreciation | D21: 0 | E21: 0 | F21: 0
A22: EBIT | C22: ='INCOME STATEMENT'!F22 -> 7333474245 | D22: =+D18+D21 -> 2.9468881e+09 | E22: =+E18+E21 -> 1.4577166e+10 | F22: =+F18+F21 -> 2.9149519e+10 | H22: =D22/D$6 -> 0.039236159 | I22: =E22/E$6 -> 0.1577359 | J22: =F22/F$6 -> 0.25634419 | K22: =AVERAGE(H22:J22) -> 0.15110542
B23: EBIT margin | C23: ='INCOME STATEMENT'!F23 -> 0.12014287 | D23: =+D22/D6 -> 0.039236159 | E23: =+E22/E6 -> 0.1577359 | F23: =+F22/F6 -> 0.25634419 | H23: =D23/D$6 -> 5.2240741e-13 | I23: =E23/E$6 -> 1.7068212e-12 | J23: =F23/F$6 -> 2.2543199e-12 | K23: =AVERAGE(H23:J23) -> 1.4945162e-12
A25: Other incomes/(charges):
B26: interest income | E26: 0 | F26: 0 | H26: =D26/D$6 -> 0 | I26: =E26/E$6 -> 0 | J26: =F26/F$6 -> 0 | K26: =AVERAGE(H26:J26) -> 0
B27: interest expense | C27: ='INCOME STATEMENT'!F27 -> -19483450 | D27: -7125134289 | E27: -2738870436 | F27: -7038891365 | H27: =D27/D$6 -> -0.09486716 | I27: =E27/E$6 -> -0.029636639 | J27: =F27/F$6 -> -0.061900811 | K27: =AVERAGE(H27:J27) -> -0.06213487
A28: Other incomes/(charges) | C28: ='INCOME STATEMENT'!F28 -> 85716770 | D28: =+D26+D27 -> -7125134289 | E28: =+E26+E27 -> -2738870436 | F28: =+F26+F27 -> -7038891365 | H28: =D28/D$6 -> -0.09486716 | I28: =E28/E$6 -> -0.029636639 | J28: =F28/F$6 -> -0.061900811 | K28: =AVERAGE(H28:J28) -> -0.06213487
A30: Non Operating Income | C30: ='INCOME STATEMENT'!F30 -> 0 | D30: =1006370564+264951236 -> 1271321800 | E30: =186392498+422783588 -> 609176086 | F30: =248115634+176467247 -> 424582881 | H30: =D30/D$6 -> 0.016926936 | I30: =E30/E$6 -> 0.0065917436 | J30: =F30/F$6 -> 0.0037338301 | K30: =AVERAGE(H30:J30) -> 0.0090841697
A32: Profit Before Tax | C32: ='INCOME STATEMENT'!F32 -> 7419191015 | D32: =+D22+D28+D30 -> -2.9069244e+09 | E32: =+E22+E28+E30 -> 1.2447472e+10 | F32: =+F22+F28+F30 -> 2.2535211e+10 | H32: =D32/D$6 -> -0.038704066 | I32: =E32/E$6 -> 0.13469101 | J32: =F32/F$6 -> 0.19817721 | K32: =AVERAGE(H32:J32) -> 0.098054717
A33: Corporate Tax | C33: ='INCOME STATEMENT'!F33 -> -1613364280 | D33: =-14866516500+1492188624 -> -13374327876 | E33: =-17448959880-558003573-93012389 -> -18099975842 | F33: =-30675449200+823736312-38822794 -> -29890535682 | J33: =(F33-E33)/E33 -> 0.65141302
A35: Net Profit After Tax | C35: ='INCOME STATEMENT'!F35 -> 5805826735 | D35: =+D32+D33 -> -1.6281252e+10 | E35: =+E32+E33 -> -5.6525041e+09 | F35: =+F32+F33 -> -7.3553247e+09 | H35: =D35/D$6 -> -0.21677573 | I35: =E35/E$6 -> -0.061164348 | J35: =F35/F$6 -> -0.064683561 | K35: =AVERAGE(H35:J35) -> -0.11420788
B36: Net Profit margin | D36: =+D35/D6 -> -0.21677573 | E36: =+E35/E6 -> -0.061164348 | F36: =+F35/F6 -> -0.064683561 | I36: =J35-I35 -> -0.0035192135

Sheet ACC PAYABLES
A1: =HOME!B4 -> PT RAJA VOLTAMA ELEKTRIK
A2: Bank Loan Schedules
A3: ='BALANCE SHEET'!A3 -> (IDR)
C5: ='FIXED ASSET'!C5 -> 2019 | D5: ='FIXED ASSET'!D5 -> 2020 | E5: ='FIXED ASSET'!E5 -> 2021
A7: Bank loan-SHORT TERM
A8: Principal
A9: Beginning | C9: 0 | D9: 0 | E9: 0
B10: Addition | C10: 0 | D10: 0 | E10: 0
B11: Repayment | C11: 0 | D11: 0 | E11: 0
A12: Ending | C12: =SUM(C9:C11) -> 0 | D12: =SUM(D9:D11) -> 0 | E12: =SUM(E9:E11) -> 0
A14: Interest Payable | C14: 0 | D14: 0 | E14: 0
A16: Bank loan-LONG TERM | C16: 8
A17: Principal | C17: 0.13 | D17: 0.13 | E17: 0.13
A18: Beginning | C18: 0 | D18: =C21 -> 0 | E18: =D21 -> 0
B19: Addition | C19: 0 | D19: 0 | E19: 0
B20: Repayment | C20: 0 | D20: 0 | E20: 0
A21: Ending | C21: =SUM(C18:C20) -> 0 | D21: =SUM(D18:D20) -> 0 | E21: =SUM(E18:E20) -> 0
A23: Interest Payable | C23: 0 | D23: 0 | E23: 0

Sheet RESUME
A1: Accounts | B1: ='BALANCE SHEET'!C4 -> 2018 | C1: ='BALANCE SHEET'!D4 -> 2019 | D1: ='BALANCE SHEET'!E4 -> 2020 | E1: ='BALANCE SHEET'!F4 -> 2021 | F1: ='PROY BALANCE SHEET'!D5&"P" -> 2022P | G1: ='PROY BALANCE SHEET'!E5&"P" -> 2023P | H1: ='PROY BALANCE SHEET'!F5&"P" -> 2024P
A2: Current Assets | B2: ='BALANCE SHEET'!C16 -> 19169235881 | C2: ='BALANCE SHEET'!D16 -> 19602444657 | D2: ='BALANCE SHEET'!E16 -> 23960644462 | E2: ='BALANCE SHEET'!F16 -> 27371778788 | F2: ='PROY BALANCE SHEET'!D21 -> 5.5930366e+10 | G2: ='PROY BALANCE SHEET'!E21 -> 6.9286924e+11 | H2: ='PROY BALANCE SHEET'!F21 -> 1.0527284e+13
A3: Total Non Current Asset | B3: ='BALANCE SHEET'!C25 -> 31069618 | C3: ='BALANCE SHEET'!D25 -> 6123781380 | D3: ='BALANCE SHEET'!E25 -> 6012024389 | E3: ='BALANCE SHEET'!F25 -> 6264339945 | F3: ='PROY BALANCE SHEET'!D31 -> 5.9246136e+11 | G3: ='PROY BALANCE SHEET'!E31 -> 5.9724043e+11 | H3: ='PROY BALANCE SHEET'!F31 -> 6.1665441e+11
A4: ASSETS | B4: ='BALANCE SHEET'!C27 -> 19200305499 | C4: ='BALANCE SHEET'!D27 -> 25726226037 | D4: ='BALANCE SHEET'!E27 -> 29972668851 | E4: ='BALANCE SHEET'!F27 -> 33636118733 | F4: ='PROY BALANCE SHEET'!D33 -> 6.4839172e+11 | G4: ='PROY BALANCE SHEET'!E33 -> 1.2901097e+12 | H4: ='PROY BALANCE SHEET'!F33 -> 1.1143938e+13
A5: Current Liabilities | B5: ='BALANCE SHEET'!C35 -> 4936833523 | C5: ='BALANCE SHEET'!D35 -> 7056900624 | D5: ='BALANCE SHEET'!E35 -> 6309204572 | E5: ='BALANCE SHEET'!F35 -> 4269636530 | F5: ='PROY BALANCE SHEET'!D45 -> 3.5518743e+09 | G5: ='PROY BALANCE SHEET'!E45 -> 3.0530785e+09 | H5: ='PROY BALANCE SHEET'!F45 -> 2.7253019e+09
A6: Non Current Liabilities | B6: ='BALANCE SHEET'!C40 -> 0 | C6: ='BALANCE SHEET'!D40 -> 0 | D6: ='BALANCE SHEET'!E40 -> 0 | E6: ='BALANCE SHEET'!F40 -> 0 | F6: ='PROY BALANCE SHEET'!D52 -> 0 | G6: ='PROY BALANCE SHEET'!E52 -> #DIV/0! | H6: ='PROY BALANCE SHEET'!F52 -> #DIV/0!
A7: LIABILITIES | B7: ='BALANCE SHEET'!C41 -> 4936833523 | C7: ='BALANCE SHEET'!D41 -> 7056900624 | D7: ='BALANCE SHEET'!E41 -> 6309204572 | E7: ='BALANCE SHEET'!F41 -> 4269636530 | F7: ='PROY BALANCE SHEET'!D45+'PROY BALANCE SHEET'!D52 -> 3.5518743e+09 | G7: ='PROY BALANCE SHEET'!E45+'PROY BALANCE SHEET'!E52 -> #DIV/0! | H7: ='PROY BALANCE SHEET'!F45+'PROY BALANCE SHEET'!F52 -> #DIV/0!
A8: Shareholders' Equity | B8: ='BALANCE SHEET'!C49 -> 14263471976 | C8: ='BALANCE SHEET'!D49 -> 18669325413 | D8: ='BALANCE SHEET'!E49 -> 23663464279 | E8: ='BALANCE SHEET'!F49 -> 29366482204 | F8: ='PROY BALANCE SHEET'!D60 -> 3.5999026e+10 | G8: ='PROY BALANCE SHEET'!E60 -> 4.3899512e+10 | H8: ='PROY BALANCE SHEET'!F60 -> 5.2804375e+10
A9: LIABILITES & EQUITY | B9: ='BALANCE SHEET'!C51 -> 19200305499 | C9: ='BALANCE SHEET'!D51 -> 25726226037 | D9: ='BALANCE SHEET'!E51 -> 29972668851 | E9: ='BALANCE SHEET'!F51 -> 33636118734 | F9: ='PROY BALANCE SHEET'!D62 -> 3.95509e+10 | G9: ='PROY BALANCE SHEET'!E62 -> #DIV/0! | H9: ='PROY BALANCE SHEET'!F62 -> #DIV/0!
A10: Revenue | B10: ='INCOME STATEMENT'!C6 -> 34193458257 | C10: ='INCOME STATEMENT'!D6 -> 52109888424 | D10: ='INCOME STATEMENT'!E6 -> 59340130084 | E10: ='INCOME STATEMENT'!F6 -> 61039612496 | F10: ='PROY LR'!D8 -> 7.5106436e+10 | G10: ='PROY LR'!E8 -> 9.2415015e+10 | H10: ='PROY LR'!F8 -> 1.1371243e+11
A11: COGS | B11: ='INCOME STATEMENT'!C7 -> -18945063902 | C11: ='INCOME STATEMENT'!D7 -> -33239782127 | D11: ='INCOME STATEMENT'!E7 -> -35270814040 | E11: ='INCOME STATEMENT'!F7 -> -26008410685 | F11: ='PROY LR'!D10 -> -4.1517664e+10 | G11: ='PROY LR'!E10 -> -5.1085576e+10 | H11: ='PROY LR'!F10 -> -6.2858452e+10
A12: Gross Profit | B12: ='INCOME STATEMENT'!C8 -> 15248394355 | C12: ='INCOME STATEMENT'!D8 -> 18870106297 | D12: ='INCOME STATEMENT'!E8 -> 24069316044 | E12: ='INCOME STATEMENT'!F8 -> 35031201811 | F12: ='PROY LR'!D11 -> 3.3588772e+10 | G12: ='PROY LR'!E11 -> 4.1329439e+10 | H12: ='PROY LR'!F11 -> 5.0853974e+10
A13: Operating Expenses | B13: ='INCOME STATEMENT'!C15 -> -11399852334 | C13: ='INCOME STATEMENT'!D15 -> -12821759310 | D13: ='INCOME STATEMENT'!E15 -> -17655896739 | E13: ='INCOME STATEMENT'!F15 -> -27537755079 | F13: ='PROY LR'!D17 -> -2.4903671e+10 | G13: ='PROY LR'!E17 -> -3.0642822e+10 | H13: ='PROY LR'!F17 -> -3.7704583e+10
A14: EBITDA | B14: ='INCOME STATEMENT'!C18 -> 3848542021 | C14: ='INCOME STATEMENT'!D18 -> 6048346987 | D14: ='INCOME STATEMENT'!E18 -> 6413419305 | E14: ='INCOME STATEMENT'!F18 -> 7493446732 | F14: ='PROY LR'!D19 -> 8.6851006e+09 | G14: ='PROY LR'!E19 -> 1.0686617e+10 | H14: ='PROY LR'!F19 -> 1.3149391e+10
A15: Depreciation/Amortization | B15: ='INCOME STATEMENT'!C21 -> -10356539 | C15: ='INCOME STATEMENT'!D21 -> -173875738 | D15: ='INCOME STATEMENT'!E21 -> -161342991 | E15: ='INCOME STATEMENT'!F21 -> -159972487 | F15: ='PROY LR'!D22 -> -2.6770894e+08 | G15: ='PROY LR'!E22 -> -6.4381026e+08 | H15: ='PROY LR'!F22 -> -1.8190746e+09
A16: EBIT | B16: ='INCOME STATEMENT'!C22 -> 3838185482 | C16: ='INCOME STATEMENT'!D22 -> 5874471249 | D16: ='INCOME STATEMENT'!E22 -> 6252076314 | E16: ='INCOME STATEMENT'!F22 -> 7333474245 | F16: ='PROY LR'!D25 -> 8.4173917e+09 | G16: ='PROY LR'!E25 -> 1.0042807e+10 | H16: ='PROY LR'!F25 -> 1.1330316e+10
A17: Other Incomes/(Charges) | B17: ='INCOME STATEMENT'!C28 -> 0 | C17: ='INCOME STATEMENT'!D28 -> 0 | D17: ='INCOME STATEMENT'!E28 -> 117519272 | E17: ='INCOME STATEMENT'!F28 -> 85716770 | F17: ='PROY LR'!D33 -> 85869304 | G17: ='PROY LR'!E33 -> 86022043 | H17: ='PROY LR'!F33 -> 86174987
A18: Non Operating Income | B18: ='INCOME STATEMENT'!C30 -> 960214518 | C18: ='INCOME STATEMENT'!D30 -> 0 | D18: ='INCOME STATEMENT'!E30 -> 0 | E18: ='INCOME STATEMENT'!F30 -> 0 | F18: ='PROY LR'!D34 -> 0 | G18: ='PROY LR'!E34 -> 0 | H18: ='PROY LR'!F34 -> 0
A19: Profit Before Tax | B19: ='INCOME STATEMENT'!C32 -> 4798400000 | C19: ='INCOME STATEMENT'!D32 -> 5874471249 | D19: ='INCOME STATEMENT'!E32 -> 6369595586 | E19: ='INCOME STATEMENT'!F32 -> 7419191015 | F19: ='PROY LR'!D36 -> 8.503261e+09 | G19: ='PROY LR'!E36 -> 1.0128829e+10 | H19: ='PROY LR'!F36 -> 1.1416491e+10
A20: Corporate Tax | B20: ='INCOME STATEMENT'!C33 -> -1117701375 | C20: ='INCOME STATEMENT'!D33 -> -1468617812 | D20: ='INCOME STATEMENT'!E33 -> -1375456720 | E20: ='INCOME STATEMENT'!F33 -> -1613364280 | F20: ='PROY LR'!D37 -> -1.8707174e+09 | G20: ='PROY LR'!E37 -> -2.2283423e+09 | H20: ='PROY LR'!F37 -> -2.511628e+09
A21: Net Profit After Tax | B21: ='INCOME STATEMENT'!C35 -> 3680698625 | C21: ='INCOME STATEMENT'!D35 -> 4405853437 | D21: ='INCOME STATEMENT'!E35 -> 4994138866 | E21: ='INCOME STATEMENT'!F35 -> 5805826735 | F21: ='PROY LR'!D39 -> 6.6325436e+09 | G21: ='PROY LR'!E39 -> 7.9004864e+09 | H21: ='PROY LR'!F39 -> 8.904863e+09
A22: Land | C22: ='FIXED ASSET'!C63 -> 0 | D22: ='FIXED ASSET'!D63 -> 0 | E22: ='FIXED ASSET'!E63 -> 0 | F22: ='PROY FIXED ASSETS'!D63 -> 105632336296 | G22: ='PROY FIXED ASSETS'!E63 -> 105632336296 | H22: ='PROY FIXED ASSETS'!F63 -> 105632336296
A23: Building | C23: ='FIXED ASSET'!C64 -> 4947437500 | D23: ='FIXED ASSET'!D64 -> 4947437500 | E23: ='FIXED ASSET'!E64 -> 4947437500 | F23: ='PROY FIXED ASSETS'!D64 -> 163209838554 | G23: ='PROY FIXED ASSETS'!E64 -> 163209838554 | H23: ='PROY FIXED ASSETS'!F64 -> 163209838554
A24: Machinery, Vehicle, Fixture, FurnitUre, etc | C24: =SUM('FIXED ASSET'!C65:C68) -> 1176343880 | D24: =SUM('FIXED ASSET'!D65:D68) -> 1064586889 | E24: =SUM('FIXED ASSET'!E65:E68) -> 1316902445 | F24: =SUM('PROY FIXED ASSETS'!D65:D68) -> 3.2361918e+11 | G24: =SUM('PROY FIXED ASSETS'!E65:E68) -> 3.2839825e+11 | H24: =SUM('PROY FIXED ASSETS'!F65:F68) -> 3.4781223e+11

Sheet CFI
A1: =HOME!B4 -> PT RAJA VOLTAMA ELEKTRIK
A2: Cash Flow Available to Investors (CFI)
A3: ='BALANCE SHEET'!A3 -> (IDR)
E4: PROYEKSI
B5: =FCF!C5 -> 2019 | C5: =B5+1 -> 2020 | D5: =C5+1 -> 2021 | E5: =D5+1 -> 2022 | F5: =E5+1 -> 2023 | G5: =F5+1 -> 2024 | H5: =G5+1 -> 2025 | I5: =H5+1 -> 2026 | J5: =I5+1 -> 2027 | K5: =J5+1 -> 2028
A7: Free Cash Flow | B7: =FCF!C20 -> -1280082601 | C7: =FCF!D20 -> 1483348156 | D7: =FCF!E20 -> 5021507390 | E7: =DCF!D20 -> -3.6528652e+10 | F7: =DCF!E20 -> -6.3446109e+11 | G7: =DCF!F20 -> -9.8453952e+12 | H7: =DCF!G20 -> 0 | I7: =DCF!H20 -> 0 | J7: =DCF!I20 -> 0 | K7: =DCF!J20 -> 0
